syntax error, unexpected $end, expecting SCAN_ATTR or SCAN_DATASET or SCAN_ERROR
context: ^
<xarray.Dataset>
Dimensions:  (time: 2861, lat: 313, lon: 263, depth: 40)
Coordinates:
  * depth    (depth) float64 0.0 2.0 4.0 6.0 8.0 ... 2.5e+03 3e+03 4e+03 5e+03
  * lat      (lat) float64 -40.0 -39.92 -39.84 -39.76 ... -15.2 -15.12 -15.04
  * lon      (lon) float64 -90.0 -89.92 -89.84 -89.76 ... -69.2 -69.12 -69.04
  * time     (time) datetime64[ns] 2015-01-01T12:00:00 ... 2015-12-31T09:00:00
Data variables:
    zos      (time, lat, lon) float32 ...
    thetao   (time, depth, lat, lon) float32 ...
    so       (time, depth, lat, lon) float32 ...
    uo       (time, depth, lat, lon) float32 ...
    vo       (time, depth, lat, lon) float32 ...
Attributes:
    classification_level:      UNCLASSIFIED
    distribution_statement:    Approved for public release. Distribution unli...
    downgrade_date:            not applicable
    classification_authority:  not applicable
    institution:               Naval Oceanographic Office
    source:                    HYCOM archive file
    history:                   archv2ncdf3z
    field_type:                instantaneous
    Conventions:               CF-1.6 NAVO_netcdf_v1.1
Downloading data for  Y2015M01 please wait...
Resampling
Saving...
Downloading data for  Y2015M02 please wait...
Resampling
Saving...
Downloading data for  Y2015M03 please wait...
Resampling
Saving...
Downloading data for  Y2015M04 please wait...
Resampling
Saving...
Downloading data for  Y2015M05 please wait...
Resampling
Saving...
Downloading data for  Y2015M06 please wait...
Resampling
Saving...
Downloading data for  Y2015M07 please wait...
Resampling
Saving...
Downloading data for  Y2015M08 please wait...
Resampling
Saving...
Downloading data for  Y2015M09 please wait...
Resampling
Saving...
Downloading data for  Y2015M10 please wait...
Resampling
Saving...
Downloading data for  Y2015M11 please wait...
Resampling
Saving...
Downloading data for  Y2015M12 please wait...
Resampling
Saving...
Traceback (most recent call last):
  File "/home/lucas/miniconda3/envs/main/lib/python3.8/site-packages/xarray/backends/file_manager.py", line 209, in _acquire_with_cache_info
    file = self._cache[self._key]
  File "/home/lucas/miniconda3/envs/main/lib/python3.8/site-packages/xarray/backends/lru_cache.py", line 55, in __getitem__
    value = self._cache[key]
KeyError: [<class 'netCDF4._netCDF4.Dataset'>, ('https://<Lucas.Glasner:y4vkrp7lqcv>@tds.hycom.org/thredds/dodsC/GLBv0.08/expt_53.X/data/2016',), 'r', (('clobber', True), ('diskless', False), ('format', 'NETCDF4'), ('persist', False)), 'a1ea5dfb-0f04-43b1-b81e-0a81d40f8566']

During handling of the above exception, another exception occurred:

Traceback (most recent call last):
  File "download_hycom_reanalysis.py", line 47, in <module>
    data = get_hycom_reanalysis(year=yr,
  File "download_hycom_reanalysis.py", line 35, in get_hycom_reanalysis
    data = xr.open_dataset(url, decode_times=False)
  File "/home/lucas/miniconda3/envs/main/lib/python3.8/site-packages/xarray/backends/api.py", line 539, in open_dataset
    backend_ds = backend.open_dataset(
  File "/home/lucas/miniconda3/envs/main/lib/python3.8/site-packages/xarray/backends/netCDF4_.py", line 572, in open_dataset
    store = NetCDF4DataStore.open(
  File "/home/lucas/miniconda3/envs/main/lib/python3.8/site-packages/xarray/backends/netCDF4_.py", line 376, in open
    return cls(manager, group=group, mode=mode, lock=lock, autoclose=autoclose)
  File "/home/lucas/miniconda3/envs/main/lib/python3.8/site-packages/xarray/backends/netCDF4_.py", line 323, in __init__
    self.format = self.ds.data_model
  File "/home/lucas/miniconda3/envs/main/lib/python3.8/site-packages/xarray/backends/netCDF4_.py", line 385, in ds
    return self._acquire()
  File "/home/lucas/miniconda3/envs/main/lib/python3.8/site-packages/xarray/backends/netCDF4_.py", line 379, in _acquire
    with self._manager.acquire_context(needs_lock) as root:
  File "/home/lucas/miniconda3/envs/main/lib/python3.8/contextlib.py", line 113, in __enter__
    return next(self.gen)
  File "/home/lucas/miniconda3/envs/main/lib/python3.8/site-packages/xarray/backends/file_manager.py", line 197, in acquire_context
    file, cached = self._acquire_with_cache_info(needs_lock)
  File "/home/lucas/miniconda3/envs/main/lib/python3.8/site-packages/xarray/backends/file_manager.py", line 215, in _acquire_with_cache_info
    file = self._opener(*self._args, **kwargs)
  File "src/netCDF4/_netCDF4.pyx", line 2330, in netCDF4._netCDF4.Dataset.__init__
  File "src/netCDF4/_netCDF4.pyx", line 1948, in netCDF4._netCDF4._ensure_nc_success
OSError: [Errno -72] NetCDF: Malformed or inaccessible DAP2 DDS or DAP4 DMR response: b'https://<Lucas.Glasner:y4vkrp7lqcv>@tds.hycom.org/thredds/dodsC/GLBv0.08/expt_53.X/data/2016'
